Workbook

Sheet Лист1

Sheet Дела
A1: № | B1: E-mail | C1: Телефон | D1: Сайт ответчика | E1: Ссылка на дело | F1: Номер дела | G1: Истец сокращенно | H1: ИНН Истца | I1: Ответчик сокращенно | J1: ИНН Ответчика | K1: Руководитель ответчика | L1: ИНН руководителя ответчика | M1: Сумма иска | N1: Дата подачи иска | O1: всего, судебных дел по данному ответчику | P1: Адрес ответчика | Q1: Cуд | R1: ОКВЕД Ответчика | S1: Наименование истца | T1: Ссылка на истца | U1: Наименование ответчика | V1: Ссылка на ответчика | W1: Последний акт
A2: =SUBTOTAL(103,$F$1:F2)-1 -> 1 | B2: ovchin_nn@mail.ru | C2: +7 (910) 131-18-94_x000D_ +7 (910) 143-33-00 | E2: https://kad.arbitr.ru/Card/5472b022-160c-4aab-b9b4-0d8e51681078 | F2: А40-34987/2024 | G2: ООО "Комплексная Безопасность" | H2: 5038076713 | I2: ООО "Артал Строй" | J2: 5262277538 | K2: Родионов Артем Игоревич | L2: 526211125912 | M2: 4489799 | N2: 45342 | O2: 1 | P2: 607687, Нижегородская область, Кстовский район, село Ближнее Борисово, Школьная ул, д. 18, офис 2 | Q2: АС города Москвы | R2: Производство электромонтажных, санитарно-технических и прочих строительно-монтажных работ (43.2) | S2: ОБЩЕСТВО С ОГРАНИЧЕННОЙ ОТВЕТСТВЕННОСТЬЮ "КОМПЛЕКСНАЯ БЕЗОПАСНОСТЬ" | U2: ОБЩЕСТВО С ОГРАНИЧЕННОЙ ОТВЕТСТВЕННОСТЬЮ "АРТАЛ СТРОЙ" | W2: Заявление Исковое заявление
A3: =SUBTOTAL(103,$F$1:F3)-1 -> 2 | B3: az8767@yandex.ru | E3: https://kad.arbitr.ru/Card/ad2a085e-f257-47b0-aa45-3b5f9b2ccdf9 | F3: А40-34970/2024 | G3: ИФНС России № 10 по Г. Москве | H3: 7710047253 | I3: ООО "Фортуна" | J3: 9710110269 | K3: Ооржак Олча Май Оглу | L3: 171802124419 | M3: 3174989.9 | N3: 45342 | O3: 1 | P3: 125375, город Москва, Козицкий пер, д. 1а стр. 2, помещ. 3/3 | Q3: АС города Москвы | R3: Деятельность по комплексному обслуживанию помещений (81.10) | S3: ИНСПЕКЦИЯ ФЕДЕРАЛЬНОЙ НАЛОГОВОЙ СЛУЖБЫ № 10 ПО Г. МОСКВЕ | U3: ОБЩЕСТВО С ОГРАНИЧЕННОЙ ОТВЕТСТВЕННОСТЬЮ "ФОРТУНА" | W3: Определение О принятии заявления о признании должника банкротом
A4: =SUBTOTAL(103,$F$1:F4)-1 -> 3 | B4: rzd@rzd.ru_x000D_ poddymnikovaov@wsr.ru_x000D_ DKRE-Mahalov@kbsh.rzd.ru_x000D_ dtv-3.rzd@bk.ru_x000D_ echekunova@skzd.rzd.ru_x000D_ EPBelenkaiakr@skzd.rzd.ru_x000D_ fax@css.rzd.ru_x000D_ gorkdmkadr@gmail.com_x000D_ kuzmenkovagv@center.rzd.ru_x000D_ mivc@mzd.ru_x000D_ mrzd_KostrovaSA@orw.ru_x000D_ NEKolesnikova@serw.ru_x000D_ Ngs_s@svrw.ru_x000D_ sevtcfto@yandex.ru_x000D_ TuizovaTA@mail.zabtrans.ru | C4: +7 (499) 262-99-01_x000D_ +7 (499) 262-10-02_x000D_ 8 (800) 775-00-00_x000D_ +7 (4852) 52-18-30_x000D_ +7 (3012) 28-25-04_x000D_ +7 (3022) 22-33-05_x000D_ +7 (3022) 22-46-03_x000D_ +7 (3022) 22-46-72_x000D_ +7 (3022) 22-75-05_x000D_ +7 (3022) 24-18-00_x000D_ +7 (3022) 24-22-25_x000D_ +7 (3022) 24-45-58_x000D_ +7 (30241) 2-40-54_x000D_ +7 (342) 230-22-25_x000D_ +7 (343) 358-22-25_x000D_ +7 (343) 358-22-60_x000D_ +7 (343) 358-29-32_x000D_ +7 (343) 358-40-88_x000D_ +7 (343) 358-44-00_x000D_ +7 (343) 358-48-10_x000D_ +7 (343) 358-48-48_x000D_ +7 (343) 358-48-89_x000D_ +7 (343) 358-57-27_x000D_ +7 (343) 380-14-74_x000D_ +7 (343) 380-17-54_x000D_ +7 (3435) 49-42-39_x000D_ +7 (3452) 52-31-40_x000D_ +7 (3452) 52-38-48_x000D_ +7 (3462) 39-35-33_x000D_ +7 (347) 229-63-15_x000D_ +7 (347) 253-14-52_x000D_ +7 (351) 259-29-04_x000D_ +7 (351) 263-84-82_x000D_ +7 (351) 268-21-40_x000D_ +7 (351) 268-39-12_x000D_ +7 (351) 268-65-09_x000D_ +7 (3513) 69-21-40_x000D_ +7 (3812) 44-30-79_x000D_ +7 (383) 229-20-20_x000D_ +7 (383) 229-36-02_x000D_ +7 (383) 229-48-02_x000D_ +7 (383) 229-50-27_x000D_ +7 (383) 334-02-43_x000D_ +7 (3842) 32-23-79_x000D_ +7 (3842) 32-39-50_x000D_ +7 (3852) 29-20-48_x000D_ +7 (3902) 29-45-66_x000D_ +7 (3912) 23-13-28_x000D_ +7 (3912) 48-04-35_x000D_ +7 (3912) 48-05-59_x000D_ +7 (3912) 59-52-98_x000D_ +7 (3952) 63-22-46_x000D_ +7 (3952) 63-42-66_x000D_ +7 (3952) 63-84-79_x000D_ +7 (3952) 64-42-46_x000D_ +7 (3952) 64-48-48_x000D_ +7 (3952) 64-51-55_x000D_ +7 (3953) 49-79-79_x000D_ +7 (4012) 58-61-01_x000D_ +7 (4012) 58-72-02_x000D_ +7 (41656) 7-20-00_x000D_ +7 (4212) 38-12-27_x000D_ +7 (4212) 38-37-18_x000D_ +7 (4212) 38-38-80_x000D_ +7 (4212) 38-41-36_x000D_ +7 (4212) 38-47-19_x000D_ +7 (4212) 38-48-43_x000D_ +7 (4212) 38-48-48_x000D_ +7 (4212) 38-53-57_x000D_ +7 (4212) 38-81-91_x000D_ +7 (4212) 38-88-34_x000D_ +7 (4712) 55-23-00_x000D_ +7 (4712) 55-57-54_x000D_ +7 (4722) 76-03-04_x000D_ +7 (4722) 76-05-25_x000D_ +7 (4732) 48-83-14_x000D_ +7 (4732) 65-08-10_x000D_ +7 (4732) 65-08-28_x000D_ +7 (4732) 65-22-64_x000D_ +7 (4732) 65-23-51_x000D_ +7 (4732) 65-28-32_x000D_ +7 (4732) 65-38-34_x000D_ +7 (4732) 65-44-50_x000D_ +7 (4732) 65-66-22_x000D_ +7 (4732) 65-72-81_x000D_ +7 (47391) 4-17-26_x000D_ +7 (47391) 7-59-64_x000D_ +7 (47545) 3-21-40_x000D_ +7 (47545) 3-22-76_x000D_ +7 (4812) 39-52-25_x000D_ +7 (4842) 78-52-95_x000D_ +7 (4852) 49-50-02_x000D_ +7 (4852) 52-40-86_x000D_ +7 (4852) 52-52-43_x000D_ +7 (4852) 79-22-41_x000D_ +7 (4852) 79-35-60_x000D_ +7 (4852) 79-43-14_x000D_ +7 (4852) 79-44-00_x000D_ +7 (4872) 20-20-80_x000D_ +7 (4872) 20-20-93 | D4: http://www.e-disclosure.ru/portal/company.aspx?id=4543_x000D_ http://www.rzd.ru/_x000D_ http://altaitursib.ru/_x000D_ http://dss-sverdl.ru/_x000D_ http://dzvr.ru/about/structure/_x000D_ http://krw.ru/_x000D_ http://kzd.web.rzd/_x000D_ http://rzd.ru/_x000D_ http://www.cm.rzd.ru/_x000D_ http://www.css-rzd.ru/_x000D_ http://www.kras.rzd.ru/_x000D_ http://www.nrr.cm.rzd.ru/_x000D_ http://www.pkbct.ru/_x000D_ http://www.rmzhoper.ru/_x000D_ http://www.rzd.ru/ent/public/ru?STRUCTURE_ID=5185&amp;layer_id=5554&amp;refererLayerId=5553&amp;id=1015_x000D_ http://www.rzd.ru/ent/public/ru?STRUCTURE_ID=5185&amp;layer_id=5554&amp;refererLayerId=5553&amp;id=4347_x000D_ http://www.trudvsem.ru/_x000D_ http://www.uvzd.rzd.ru/_x000D_ http://www.web.rzd/_x000D_ https://www.list-org.com/go?site=804719 | E4: https://kad.arbitr.ru/Card/6eac2fac-753c-4acd-8fe0-fbcbcbd534ba | F4: А40-34838/2024 | G4: АО "Нефтетранссервис" | H4: 7731537410 | I4: ОАО "РЖД" | J4: 7708503727 | K4: Белозёров Олег Валентинович | L4: 781306504007 | M4: 1118159 | N4: 45342 | O4: 220412 | P4: 107174, город Москва, Новая Басманная ул, д. 2/1 стр. 1 | Q4: АС города Москвы | R4: Деятельность железнодорожного транспорта: грузовые перевозки (49.20) | S4: АКЦИОНЕРНОЕ ОБЩЕСТВО "НЕФТЕТРАНССЕРВИС" | U4: ОТКРЫТОЕ АКЦИОНЕРНОЕ ОБЩЕСТВО "РОССИЙСКИЕ ЖЕЛЕЗНЫЕ ДОРОГИ" | W4: Заявление Исковое заявление
A5: =SUBTOTAL(103,$F$1:F5)-1 -> 4 | C5: +7 (916) 428-25-05 | E5: https://kad.arbitr.ru/Card/e429a3d5-ded7-42bd-a388-6a75c4919dee | F5: А40-34726/2024 | G5: ООО "Акрополь Инжиниринг" | H5: 7706682252 | I5: ООО "НЖС" | J5: 7728420282 | K5: Шевацуков Константин Юрьевич | L5: 010517174225 | M5: 4306490.7 | N5: 45342 | O5: 74 | P5: 115184, город Москва, Большая Татарская ул., д. 35 стр. 3, э 5 п II к 2-4,9 ч/к 1,5,10 | Q5: АС города Москвы | R5: Торговля оптовая лесоматериалами, строительными материалами и санитарно-техническим оборудованием (46.73) | S5: ОБЩЕСТВО С ОГРАНИЧЕННОЙ ОТВЕТСТВЕННОСТЬЮ "АКРОПОЛЬ ИНЖИНИРИНГ" | U5: ОБЩЕСТВО С ОГРАНИЧЕННОЙ ОТВЕТСТВЕННОСТЬЮ "НЖСТРОЙ" | W5: Заявление Исковое заявление
A6: =SUBTOTAL(103,$F$1:F6)-1 -> 5 | E6: https://kad.arbitr.ru/Card/af4fa098-eda4-470d-9bab-7ced56ed221a | F6: А40-34801/2024 | G6: ООО "Екс-Групп" | H6: 7723435782 | I6: ИП Гасангусейнов Вазир Султанович | J6: 052600742828 | K6: Гасангусейнов Вазир Султанович | L6: 052600742828 | M6: 611481 | N6: 45342 | O6: 1 | P6: Калужская область, Жуковский район, город Белоусово | Q6: АС города Москвы | R6: Деятельность легкового такси и арендованных легковых автомобилей с водителем (49.32) | S6: ОБЩЕСТВО С ОГРАНИЧЕННОЙ ОТВЕТСТВЕННОСТЬЮ "ЕКС-ГРУПП" | U6: ИП Гасангусейнов Вазир Султанович | W6: Заявление Исковое заявление
A7: =SUBTOTAL(103,$F$1:F7)-1 -> 6 | C7: +7 (495) 120-28-80 | D7: http://hotsto.ru/ | E7: https://kad.arbitr.ru/Card/be5bb01c-cf29-4565-8732-313c24509676 | F7: А40-34707/2024 | G7: Департамент городского Имущества Города Москвы | H7: 7705031674 | I7: ООО "Горячий Ключ" | J7: 7725457502 | K7: Асгарли Алигулу Ильгар Оглы | L7: 972905922903 | M7: 663120.56 | N7: 45342 | O7: 9 | P7: 125480, город Москва, Туристская ул, д. 20 к. 1, помещ. XVI ком. 3 | Q7: АС города Москвы | R7: Аренда и управление собственным или арендованным недвижимым имуществом (68.20) | S7: ДЕПАРТАМЕНТ ГОРОДСКОГО ИМУЩЕСТВА ГОРОДА МОСКВЫ | U7: ОБЩЕСТВО С ОГРАНИЧЕННОЙ ОТВЕТСТВЕННОСТЬЮ "ГОРЯЧИЙ КЛЮЧ" | W7: Заявление Исковое заявление
A8: =SUBTOTAL(103,$F$1:F8)-1 -> 7 | B8: info@1vrk.ru_x000D_ ovalenkorv@center.rzd.ru_x000D_ alsm_reception@1vrk.ru_x000D_ alzm_reception@1vrk.ru_x000D_ alzm_sokolovaes@1vrk.ru_x000D_ aovrk@mail.ru_x000D_ filatovanb@1vrk.ru_x000D_ grishakovaes@1vrk.ru_x000D_ it@1vrk.ru_x000D_ lydmilka4832@yandex.ru_x000D_ makovaea@irk.esr.ru_x000D_ makovaea@irk.esrr.ru_x000D_ makovaev@irk.esrr.ru_x000D_ makovaeva@irk.esrr.ru_x000D_ martynovaaa@1vrk.ru_x000D_ pl2@mail.ru_x000D_ pl_2@mail.ru_x000D_ posiseevann@1vrk.rzd_x000D_ pl_2bryansk@mail.ru_x000D_ ulan_krivolapovaaa@1vrk.rzd_x000D_ vchd12_komarovaOO@psk.orw.rzd | C8: +7 (499) 260-40-00_x000D_ +7 (4832) 60-55-48_x000D_ +7 (4832) 63-02-26_x000D_ +7 (4832) 60-22-22_x000D_ +7 (3955) 75-57-30_x000D_ +7 (3955) 75-57-33_x000D_ +7 (3955) 76-14-06_x000D_ +7 (499) 262-28-46_x000D_ +7 (950) 089-92-94_x000D_ +7 (3012) 28-21-71_x000D_ +7 (499) 260-40-50_x000D_ +7 (812) 436-61-53_x000D_ +7 (81837) 6-26-43_x000D_ +7 (84663) 2-19-75_x000D_ +7 (863) 259-08-48_x000D_ +7 (914) 176-98-95_x000D_ +7 (3955) 75-57-36_x000D_ +7 (950) 075-17-94_x000D_ +7 (812) 436-61-44_x000D_ +7 (383) 337-94-01_x000D_ +7 (3519) 44-72-22_x000D_ +7 (499) 260-71-22_x000D_ +7 (3012) 28-22-22_x000D_ +7 (3012) 28-22-58_x000D_ +7 (34256) 9-22-22_x000D_ +7 (343) 310-90-69_x000D_ +7 (343) 310-91-65_x000D_ +7 (34551) 5-22-22_x000D_ +7 (34551) 5-26-87_x000D_ +7 (3812) 44-20-61_x000D_ +7 (3812) 44-21-65_x000D_ +7 (3812) 44-99-33_x000D_ +7 (383) 229-92-87_x000D_ +7 (38448) 2-24-39_x000D_ +7 (38456) 7-37-64_x000D_ +7 (39563) 5-32-20_x000D_ +7 (39563) 5-38-40_x000D_ +7 (4212) 38-82-58_x000D_ +7 (4234) 25-30-35_x000D_ +7 (4234) 38-15-35_x000D_ +7 (42355) 4-24-21_x000D_ +7 (4725) 41-17-52_x000D_ +7 (47376) 2-27-34_x000D_ +7 (491) 375-16-26_x000D_ +7 (49644) 2-47-55_x000D_ +7 (49644) 2-55-55_x000D_ +7 (499) 623-51-40_x000D_ +7 (499) 623-51-62_x000D_ +7 (8112) 70-71-11_x000D_ +7 (8112) 70-79-08_x000D_ +7 (81361) 2-01-06_x000D_ +7 (81361) 2-80-04_x000D_ +7 (8142) 79-36-04_x000D_ +7 (8142) 79-36-75_x000D_ +7 (81533) 3-36-04_x000D_ +7 (81533) 4-33-02_x000D_ +7 (8172) 79-69-61_x000D_ +7 (81837) 6-22-22_x000D_ +7 (831) 248-52-22_x000D_ +7 (833) 260-52-22_x000D_ +7 (833) 260-61-00_x000D_ +7 (8412) 58-72-22_x000D_ +7 (8412) 58-72-64_x000D_ +7 (8452) 41-38-69_x000D_ +7 (8452) 41-75-09_x000D_ +7 (846) 303-95-00_x000D_ +7 (846) 303-95-39_x000D_ +7 (8464) 33-32-80, доб 6_x000D_ +7 (8464) 33-38-40, доб 6_x000D_ +7 (84663) 2-19-74_x000D_ +7 (8512) 32-52-55_x000D_ +7 (8612) 14-79-14_x000D_ +7 (863) 259-08-50_x000D_ +7 (863) 259-48-91_x000D_ +7 (86354) 4-54-37_x000D_ +7 (911) 957-27-96_x000D_ +7 (915) 607-33-06_x000D_ +7 (918) 508-91-11_x000D_ +7 (960) 993-79-10_x000D_ +7 (984) 277-02-89_x000D_ +7 (499) 260-00-00_x000D_ +7 (3955) 77-26-10_x000D_ +7 (4832) 60-32-33, доб 7070_x000D_ +7 (4832) 60-39-49_x000D_ +7 (4832) 60-22-56_x000D_ +7 (499) 260-49-09_x000D_ +7 (499) 260-49-66_x000D_ +7 (86354) 4-23-61_x000D_ +7 (499) 262-66-66_x000D_ +7 (846) 303-95-02, доб 303_x000D_ +7 (950) 630-39-53, доб 9_x000D_ +7 (495) 260-40-00_x000D_ +7 (499) 262-00-58_x000D_ +7 (4212) 31-58-56_x000D_ +7 (39173) 9-31-97_x000D_ +7 (846) 303-95-02_x000D_ +7 (812) 457-53-88_x000D_ +7 (812) 436-20-36_x000D_ +7 (911) 848-78-23_x000D_ +7 (499) 260-40-68 | D8: http://1vrk.ru/_x000D_ http://www.1vrk.ru/ | E8: https://kad.arbitr.ru/Card/bcb1cce1-9a5e-4605-a4c7-7b5a5c91dee7 | F8: А40-34588/2024 | G8: АО "Уголь-Транс" | H8: 5047210316 | I8: АО "ВРК-1" | J8: 7708737490 | K8: Белюгин Владимир Николаевич | L8: 614100627878 | M8: 744855.11 | N8: 45342 | O8: 15023 | P8: 129090, город Москва, Каланчевская ул., д.35 | Q8: АС города Москвы | R8: Деятельность вспомогательная, связанная с железнодорожным транспортом (52.21.1) | S8: АКЦИОНЕРНОЕ ОБЩЕСТВО "УГОЛЬ-ТРАНС" | U8: АКЦИОНЕРНОЕ ОБЩЕСТВО "ВАГОННАЯ РЕМОНТНАЯ КОМПАНИЯ - 1" | W8: Заявление Исковое заявление
A9: =SUBTOTAL(103,$F$1:F9)-1 -> 8 | E9: https://kad.arbitr.ru/Card/59ecda4f-b0e5-4a13-98a2-8c43e20e9bfc | F9: А40-34679/2024 | G9: Ассоциация СРО "Центррегион" | H9: 7722309947 | I9: ООО "Бизнес-Капитал" | J9: 7751001635 | K9: Холоднюк Дмитрий Александрович | L9: 730696467315 | M9: 506700 | N9: 45342 | O9: 4 | P9: 142134, город Москва, поселение Рязановское, поселок Знамя Октября, мкр Родники, д. 1, кв. 69 | Q9: АС города Москвы | R9: Производство прочих строительно-монтажных работ (43.29) | S9: АССОЦИАЦИЯ ПО ЗАЩИТЕ ПРАВ И ЗАКОННЫХ ИНТЕРЕСОВ ЛИЦ, ОСУЩЕСТВЛЯЮЩИХ СТРОИТЕЛЬСТВО, САМОРЕГУЛИРУЕМАЯ ОРГАНИЗАЦИЯ "ЦЕНТРРЕГИОН" | U9: ОБЩЕСТВО С ОГРАНИЧЕННОЙ ОТВЕТСТВЕННОСТЬЮ "БИЗНЕС-КАПИТАЛ" | W9: Заявление Исковое заявление
A10: =SUBTOTAL(103,$F$1:F10)-1 -> 9 | B10: gsorokina@moskomzem.ru_x000D_ ageevais@mos.ru_x000D_ barashkovaev@mos.ru_x000D_ dgi@mail.ru_x000D_ dgi@mos.ru_x000D_ dgi_news@mosa.ru_x000D_ kadyrovnn@mos.ru_x000D_ kiti0506@mail.ru_x000D_ mirskovaen@mos.ru_x000D_ polprchuv@cap.ru_x000D_ prusakovayv@mos.ru_x000D_ saraevaei@mos.ru_x000D_ zelao@mail.ru_x000D_ digm@mos.ru | C10: +7 (495) 699-72-50_x000D_ +7 (495) 959-18-02_x000D_ +7 (495) 331-02-22_x000D_ +7 (495) 587-70-87_x000D_ +7 (495) 625-45-13_x000D_ +7 (495) 634-01-27_x000D_ +7 (495) 675-46-24_x000D_ +7 (495) 953-21-56_x000D_ +7 (495) 957-75-00_x000D_ +7 (495) 959-09-75_x000D_ +7 (495) 959-19-03_x000D_ +7 (495) 959-19-13_x000D_ +7 (495) 959-19-59_x000D_ +7 (495) 959-53-39_x000D_ +7 (499) 268-56-70_x000D_ +7 (499) 380-80-84_x000D_ +7 (495) 625-45-15_x000D_ +7 (495) 777-77-77_x000D_ +7 (495) 699-20-48_x000D_ +7 (495) 362-14-63_x000D_ +7 (495) 959-19-82_x000D_ +7 (495) 957-98-53_x000D_ +7 (499) 648-05-64_x000D_ +7 (495) 959-18-88_x000D_ +7 (499) 233-97-39_x000D_ +7 (495) 959-19-55_x000D_ +7 (495) 955-53-08_x000D_ +7 (495) 122-19-27, доб 1302_x000D_ +7 (495) 955-53-79_x000D_ +7 (495) 955-51-96_x000D_ +7 (495) 955-53-68_x000D_ +7 (495) 142-12-32_x000D_ +7 (499) 649-39-23_x000D_ +7 (499) 959-18-02_x000D_ +7 (495) 959-18-22_x000D_ +7 (495) 777-77-77, доб 7_x000D_ +7 (499) 000-00-00_x000D_ +7 (495) 957-99-77 | D10: http://dgi.mos.ru/_x000D_ http://dzr.mos.ru/ | E10: https://kad.arbitr.ru/Card/ab94cc3a-d04c-413f-ac81-57b123fbe265 | F10: А40-34515/2024 | G10: АО "Специализированный Застройщик ТПУ "Рассказовка" | H10: 7701387398 | I10: Департамент городского Имущества Города Москвы | J10: 7705031674 | K10: Гаман Максим Федорович | L10: 691408455881 | M10: 330346000 | N10: 45342 | O10: 72536 | P10: 123112, город Москва, 1-й Красногвардейский пр-д, д. 21 стр. 1 | Q10: АС города Москвы | R10: Деятельность органов государственной власти субъектов Российской Федерации (республик, краев, областей), кроме судебной власти, представительств исполнительных органов государственной власти субъектов Российской Федерации при Президенте Российской Федерации (84.11.21) | S10: АКЦИОНЕРНОЕ ОБЩЕСТВО "СПЕЦИАЛИЗИРОВАННЫЙ ЗАСТРОЙЩИК ТРАНСПОРТНО-ПЕРЕСАДОЧНЫЙ УЗЕЛ "РАССКАЗОВКА" | U10: ДЕПАРТАМЕНТ ГОРОДСКОГО ИМУЩЕСТВА ГОРОДА МОСКВЫ | W10: Заявление Исковое заявление
A11: =SUBTOTAL(103,$F$1:F11)-1 -> 10 | B11: rzd@rzd.ru_x000D_ poddymnikovaov@wsr.ru_x000D_ DKRE-Mahalov@kbsh.rzd.ru_x000D_ dtv-3.rzd@bk.ru_x000D_ echekunova@skzd.rzd.ru_x000D_ EPBelenkaiakr@skzd.rzd.ru_x000D_ fax@css.rzd.ru_x000D_ gorkdmkadr@gmail.com_x000D_ kuzmenkovagv@center.rzd.ru_x000D_ mivc@mzd.ru_x000D_ mrzd_KostrovaSA@orw.ru_x000D_ NEKolesnikova@serw.ru_x000D_ Ngs_s@svrw.ru_x000D_ sevtcfto@yandex.ru_x000D_ TuizovaTA@mail.zabtrans.ru | C11: +7 (499) 262-99-01_x000D_ +7 (499) 262-10-02_x000D_ 8 (800) 775-00-00_x000D_ +7 (4852) 52-18-30_x000D_ +7 (3012) 28-25-04_x000D_ +7 (3022) 22-33-05_x000D_ +7 (3022) 22-46-03_x000D_ +7 (3022) 22-46-72_x000D_ +7 (3022) 22-75-05_x000D_ +7 (3022) 24-18-00_x000D_ +7 (3022) 24-22-25_x000D_ +7 (3022) 24-45-58_x000D_ +7 (30241) 2-40-54_x000D_ +7 (342) 230-22-25_x000D_ +7 (343) 358-22-25_x000D_ +7 (343) 358-22-60_x000D_ +7 (343) 358-29-32_x000D_ +7 (343) 358-40-88_x000D_ +7 (343) 358-44-00_x000D_ +7 (343) 358-48-10_x000D_ +7 (343) 358-48-48_x000D_ +7 (343) 358-48-89_x000D_ +7 (343) 358-57-27_x000D_ +7 (343) 380-14-74_x000D_ +7 (343) 380-17-54_x000D_ +7 (3435) 49-42-39_x000D_ +7 (3452) 52-31-40_x000D_ +7 (3452) 52-38-48_x000D_ +7 (3462) 39-35-33_x000D_ +7 (347) 229-63-15_x000D_ +7 (347) 253-14-52_x000D_ +7 (351) 259-29-04_x000D_ +7 (351) 263-84-82_x000D_ +7 (351) 268-21-40_x000D_ +7 (351) 268-39-12_x000D_ +7 (351) 268-65-09_x000D_ +7 (3513) 69-21-40_x000D_ +7 (3812) 44-30-79_x000D_ +7 (383) 229-20-20_x000D_ +7 (383) 229-36-02_x000D_ +7 (383) 229-48-02_x000D_ +7 (383) 229-50-27_x000D_ +7 (383) 334-02-43_x000D_ +7 (3842) 32-23-79_x000D_ +7 (3842) 32-39-50_x000D_ +7 (3852) 29-20-48_x000D_ +7 (3902) 29-45-66_x000D_ +7 (3912) 23-13-28_x000D_ +7 (3912) 48-04-35_x000D_ +7 (3912) 48-05-59_x000D_ +7 (3912) 59-52-98_x000D_ +7 (3952) 63-22-46_x000D_ +7 (3952) 63-42-66_x000D_ +7 (3952) 63-84-79_x000D_ +7 (3952) 64-42-46_x000D_ +7 (3952) 64-48-48_x000D_ +7 (3952) 64-51-55_x000D_ +7 (3953) 49-79-79_x000D_ +7 (4012) 58-61-01_x000D_ +7 (4012) 58-72-02_x000D_ +7 (41656) 7-20-00_x000D_ +7 (4212) 38-12-27_x000D_ +7 (4212) 38-37-18_x000D_ +7 (4212) 38-38-80_x000D_ +7 (4212) 38-41-36_x000D_ +7 (4212) 38-47-19_x000D_ +7 (4212) 38-48-43_x000D_ +7 (4212) 38-48-48_x000D_ +7 (4212) 38-53-57_x000D_ +7 (4212) 38-81-91_x000D_ +7 (4212) 38-88-34_x000D_ +7 (4712) 55-23-00_x000D_ +7 (4712) 55-57-54_x000D_ +7 (4722) 76-03-04_x000D_ +7 (4722) 76-05-25_x000D_ +7 (4732) 48-83-14_x000D_ +7 (4732) 65-08-10_x000D_ +7 (4732) 65-08-28_x000D_ +7 (4732) 65-22-64_x000D_ +7 (4732) 65-23-51_x000D_ +7 (4732) 65-28-32_x000D_ +7 (4732) 65-38-34_x000D_ +7 (4732) 65-44-50_x000D_ +7 (4732) 65-66-22_x000D_ +7 (4732) 65-72-81_x000D_ +7 (47391) 4-17-26_x000D_ +7 (47391) 7-59-64_x000D_ +7 (47545) 3-21-40_x000D_ +7 (47545) 3-22-76_x000D_ +7 (4812) 39-52-25_x000D_ +7 (4842) 78-52-95_x000D_ +7 (4852) 49-50-02_x000D_ +7 (4852) 52-40-86_x000D_ +7 (4852) 52-52-43_x000D_ +7 (4852) 79-22-41_x000D_ +7 (4852) 79-35-60_x000D_ +7 (4852) 79-43-14_x000D_ +7 (4852) 79-44-00_x000D_ +7 (4872) 20-20-80_x000D_ +7 (4872) 20-20-93 | D11: http://www.e-disclosure.ru/portal/company.aspx?id=4543_x000D_ http://www.rzd.ru/_x000D_ http://altaitursib.ru/_x000D_ http://dss-sverdl.ru/_x000D_ http://dzvr.ru/about/structure/_x000D_ http://krw.ru/_x000D_ http://kzd.web.rzd/_x000D_ http://rzd.ru/_x000D_ http://www.cm.rzd.ru/_x000D_ http://www.css-rzd.ru/_x000D_ http://www.kras.rzd.ru/_x000D_ http://www.nrr.cm.rzd.ru/_x000D_ http://www.pkbct.ru/_x000D_ http://www.rmzhoper.ru/_x000D_ http://www.rzd.ru/ent/public/ru?STRUCTURE_ID=5185&amp;layer_id=5554&amp;refererLayerId=5553&amp;id=1015_x000D_ http://www.rzd.ru/ent/public/ru?STRUCTURE_ID=5185&amp;layer_id=5554&amp;refererLayerId=5553&amp;id=4347_x000D_ http://www.trudvsem.ru/_x000D_ http://www.uvzd.rzd.ru/_x000D_ http://www.web.rzd/_x000D_ https://www.list-org.com/go?site=804719 | E11: https://kad.arbitr.ru/Card/3a21f6db-26af-410c-9ecc-a36f81016b42 | F11: А40-34376/2024 | G11: ООО "Сапфир-Агро" | H11: 4626006302 | I11: ОАО "РЖД" | J11: 7708503727 | K11: Белозёров Олег Валентинович | L11: 781306504007 | M11: 731393 | N11: 45342 | O11: 220412 | P11: 107174, город Москва, Новая Басманная ул, д. 2/1 стр. 1 | Q11: АС города Москвы | R11: Деятельность железнодорожного транспорта: грузовые перевозки (49.20) | S11: ОБЩЕСТВО С ОГРАНИЧЕННОЙ ОТВЕТСТВЕННОСТЬЮ "САПФИР-АГРО" | U11: ОТКРЫТОЕ АКЦИОНЕРНОЕ ОБЩЕСТВО "РОССИЙСКИЕ ЖЕЛЕЗНЫЕ ДОРОГИ" | W11: Заявление Исковое заявление
A12: =SUBTOTAL(103,$F$1:F12)-1 -> 11 | E12: https://kad.arbitr.ru/Card/41a9bb3f-b000-4ac2-ba55-628ca0d6c767 | F12: А40-34438/2024 | G12: АО "Трест КХМ" | H12: 7705098679 | I12: ООО "Аэрогаз" | J12: 7725715055 | K12: Имаев Салават Зайнетдинович | L12: 501301400181 | M12: 3706461.5 | N12: 45342 | O12: 2 | P12: 121205, город Москва, тер Инновационного Центра Сколково, Большой б-р, д. 42 стр. 1, помещ. 376 раб. место 11 | Q12: АС города Москвы | R12: Научные исследования и разработки в области естественных и технических наук прочие (72.19) | S12: АКЦИОНЕРНОЕ ОБЩЕСТВО "ТРЕСТ КОКСОХИММОНТАЖ" | U12: ОБЩЕСТВО С ОГРАНИЧЕННОЙ ОТВЕТСТВЕННОСТЬЮ "АЭРОГАЗ" | W12: Заявление Исковое заявление
A13: =SUBTOTAL(103,$F$1:F13)-1 -> 12 | B13: info@rst26.ru_x000D_ mup-zarya@mail.ru_x000D_ mup-zarya@yandex.ru_x000D_ shu-nn@rst26.ru_x000D_ z61380@yandex.ru_x000D_ zarya@mail.ru_x000D_ zem_ye@rst26.ru_x000D_ zarya@yandex.ru | C13: +7 (49679) 6-13-80_x000D_ +7 (49679) 6-13-79 | D13: http://www.zarya-zhilservis.ru/ | E13: https://kad.arbitr.ru/Card/f33298f7-5d05-454a-9542-f42696be9829 | F13: А40-34333/2024 | G13: АО "Мосэнергосбыт" | H13: 7736520080 | I13: ОАО "Заря-Жилсервис" | J13: 5009070386 | K13: Руднев Александр Борисович | L13: 500906686417 | M13: 1360795.4 | N13: 45342 | O13: 193 | P13: 142062, Московская область, город Домодедово, село Растуново, ул. Заря, стр. 26 | Q13: АС города Москвы | R13: Управление эксплуатацией жилого фонда за вознаграждение или на договорной основе (68.32.1) | S13: АКЦИОНЕРНОЕ ОБЩЕСТВО "МОСЭНЕРГОСБЫТ" | U13: ОТКРЫТОЕ АКЦИОНЕРНОЕ ОБЩЕСТВО "ЗАРЯ-ЖИЛСЕРВИС" | W13: Заявление Исковое заявление
A14: =SUBTOTAL(103,$F$1:F14)-1 -> 13 | B14: alexander.melnikov@foodcards.ru | E14: https://kad.arbitr.ru/Card/27165634-8e77-4687-a1b5-95427b9dab84 | F14: А40-34362/2024 | G14: ООО "Отель "Рига Ленд" | H14: 5024134531 | I14: ООО "Фуд Сервис Восток" | J14: 7725799866 | K14: Росол Артем Владимирович | L14: 324105716992 | M14: 620607.5 | N14: 45342 | O14: 36 | P14: 127287, город Москва, ул Хуторская 2-Я, д. 38а стр. 15, помещ. IX, кабинет № 64 | Q14: АС города Москвы | R14: Деятельность по предоставлению прочих вспомогательных услуг для бизнеса, не включенная в другие группировки (82.99) | S14: ОБЩЕСТВО С ОГРАНИЧЕННОЙ ОТВЕТСТВЕННОСТЬЮ "ОТЕЛЬ "РИГА ЛЕНД" | U14: ОБЩЕСТВО С ОГРАНИЧЕННОЙ ОТВЕТСТВЕННОСТЬЮ "ФУД СЕРВИС ВОСТОК" | W14: Заявление Исковое заявление
A15: =SUBTOTAL(103,$F$1:F15)-1 -> 14 | C15: +7 (383) 213-08-73 | E15: https://kad.arbitr.ru/Card/a115eafb-218f-4eed-a30b-166cfb1b3e60 | F15: А40-34332/2024 | G15: ООО "Яндекс.Такси" | H15: 7704340310 | I15: ООО "Стар" | J15: 5408017070 | K15: Головкова Евгения Александровна | L15: 540817868153 | M15: 778186.33 | N15: 45342 | O15: 11 | P15: 630117, Новосибирская область, город Новосибирск, ул. Иванова, д. 27, кв. 323 | Q15: АС города Москвы | R15: Деятельность ресторанов и услуги по доставке продуктов питания (56.10) | S15: ОБЩЕСТВО С ОГРАНИЧЕННОЙ ОТВЕТСТВЕННОСТЬЮ "ЯНДЕКС.ТАКСИ" | U15: ОБЩЕСТВО С ОГРАНИЧЕННОЙ ОТВЕТСТВЕННОСТЬЮ "СТАР" | W15: Заявление Исковое заявление
A16: =SUBTOTAL(103,$F$1:F16)-1 -> 15 | C16: +7 (926) 584-55-56 | E16: https://kad.arbitr.ru/Card/daf10b0d-4ccd-4967-82db-3753b302302f | F16: А40-34274/2024 | G16: ООО "Интегрум" | H16: 7724947688 | I16: ООО "Инком СБ" | J16: 5050100320 | K16: Кюрпя Иван Николаевич | L16: 670501775401 | M16: 671100 | N16: 45342 | O16: 18 | P16: 141103, Московская область, город Щёлково, ул. Бахчиванджи, д. 7, помещ. №4, цокольный этаж | Q16: АС города Москвы | R16: Производство электромонтажных, санитарно-технических и прочих строительно-монтажных работ (43.2) | S16: ОБЩЕСТВО С ОГРАНИЧЕННОЙ ОТВЕТСТВЕННОСТЬЮ "ИНТЕГРУМ" | U16: ОБЩЕСТВО С ОГРАНИЧЕННОЙ ОТВЕТСТВЕННОСТЬЮ "ИНТЕГРИРОВАННЫЕ КОМПЛЕКСНЫЕ СИСТЕМЫ БЕЗОПАСНОСТИ" | W16: Заявление Исковое заявление
A17: =SUBTOTAL(103,$F$1:F17)-1 -> 16 | E17: https://kad.arbitr.ru/Card/8bc3dd64-8b32-4c95-8d07-b2d14b69e4ee | F17: А40-34270/2024 | G17: ООО "Стар Строй" | H17: 7728471985 | I17: ООО "Энергопроект" | J17: 7751141921 | K17: Меджидов Шалбуз Энверович | L17: 054205291007 | M17: 3167055.1 | N17: 45342 | O17: 26 | P17: 115114, город Москва, 2-Й Павелецкий проезд, д. 5 стр. 1, подв. № 0 оф. 7 | Q17: АС города Москвы | R17: Строительство жилых и нежилых зданий (41.20) | S17: ОБЩЕСТВО С ОГРАНИЧЕННОЙ ОТВЕТСТВЕННОСТЬЮ "СТАР СТРОЙ" | U17: ОБЩЕСТВО С ОГРАНИЧЕННОЙ ОТВЕТСТВЕННОСТЬЮ "ЭНЕРГОПРОЕКТ" | W17: Заявление Исковое заявление
A18: =SUBTOTAL(103,$F$1:F18)-1 -> 17 | B18: ap@ipzavod.ru_x000D_ v.bugaeva@ipzavod.ru_x000D_ e.isaeva@ipzavod.ru_x000D_ ik@ipzavod.ru_x000D_ ns@ipzavod.ru | C18: +7 (4876) 27-04-40_x000D_ +7 (4876) 27-06-08_x000D_ +7 (910) 702-40-80_x000D_ +7 (495) 369-02-36 | E18: https://kad.arbitr.ru/Card/5d4d1879-fe27-477c-a7b0-616424d837e9 | F18: А40-33874/2024 | G18: ООО "Союз Св. Иоанна Воина" | H18: 7729705354 | I18: ООО "Тульский Винокуренный Завод 1911" | J18: 7751507541 | K18: Щербенев Сергей Николаевич | L18: 231104996872 | M18: 1907403 | N18: 45342 | O18: 29 | P18: 301733, Тульская область, Кимовский район, поселок Пронь, Заводская ул., зд. 10 стр. 23, помещ. 9 | Q18: АС города Москвы | R18: Производство дистиллированных питьевых алкогольных напитков: водки, виски, бренди, джина, ликеров и т. п. (11.01.1) | S18: ОБЩЕСТВО С ОГРАНИЧЕННОЙ ОТВЕТСТВЕННОСТЬЮ "СОЮЗ СВЯТОГО ИОАННА ВОИНА" | U18: ОБЩЕСТВО С ОГРАНИЧЕННОЙ ОТВЕТСТВЕННОСТЬЮ "ТУЛЬСКИЙ ВИНОКУРЕННЫЙ ЗАВОД 1911" | W18: Заявление Исковое заявление
A19: =SUBTOTAL(103,$F$1:F19)-1 -> 18 | B19: KLEN@vfmgei.ru_x000D_ tmacyuk@inbox.ru | C19: +7 (4842) 57-74-72_x000D_ +7 (495) 237-56-60_x000D_ +7 (8352) 34-90-38_x000D_ +7 (8617) 64-41-13_x000D_ +7 (4842) 59-75-73_x000D_ +7 (495) 237-55-40_x000D_ +7 (8352) 34-90-32_x000D_ +7 (8152) 24-62-01_x000D_ +7 (8352) 34-90-35_x000D_ +7 (8152) 24-62-04_x000D_ +7 (833) 262-13-00 | D19: http://mgei.ru/_x000D_ http://mgeitver.ru/_x000D_ http://nvr-mgei.ru/_x000D_ http://skf-mgei.ru/ | E19: https://kad.arbitr.ru/Card/b56292f7-e486-4c88-88af-826cf082c641 | F19: А40-33722/2024 | G19: Департамент городского Имущества Города Москвы | H19: 7705031674 | I19: АНО ВО МГЭУ | J19: 7737040022 | K19: Демидова Любовь Анисимовна | L19: 500601092377 | M19: 952992.01 | N19: 45342 | O19: 26 | P19: 119049, город Москва, Ленинский пр-кт, д.8 стр. 16 | Q19: АС города Москвы | R19: Образование высшее (85.22) | S19: ДЕПАРТАМЕНТ ГОРОДСКОГО ИМУЩЕСТВА ГОРОДА МОСКВЫ | U19: АВТОНОМНАЯ НЕКОММЕРЧЕСКАЯ ОРГАНИЗАЦИЯ ВЫСШЕГО ОБРАЗОВАНИЯ МОСКОВСКИЙ ГУМАНИТАРНО-ЭКОНОМИЧЕСКИЙ УНИВЕРСИТЕТ | W19: Заявление Исковое заявление
A20: =SUBTOTAL(103,$F$1:F20)-1 -> 19 | B20: rzd@rzd.ru_x000D_ poddymnikovaov@wsr.ru_x000D_ DKRE-Mahalov@kbsh.rzd.ru_x000D_ dtv-3.rzd@bk.ru_x000D_ echekunova@skzd.rzd.ru_x000D_ EPBelenkaiakr@skzd.rzd.ru_x000D_ fax@css.rzd.ru_x000D_ gorkdmkadr@gmail.com_x000D_ kuzmenkovagv@center.rzd.ru_x000D_ mivc@mzd.ru_x000D_ mrzd_KostrovaSA@orw.ru_x000D_ NEKolesnikova@serw.ru_x000D_ Ngs_s@svrw.ru_x000D_ sevtcfto@yandex.ru_x000D_ TuizovaTA@mail.zabtrans.ru | C20: +7 (499) 262-99-01_x000D_ +7 (499) 262-10-02_x000D_ 8 (800) 775-00-00_x000D_ +7 (4852) 52-18-30_x000D_ +7 (3012) 28-25-04_x000D_ +7 (3022) 22-33-05_x000D_ +7 (3022) 22-46-03_x000D_ +7 (3022) 22-46-72_x000D_ +7 (3022) 22-75-05_x000D_ +7 (3022) 24-18-00_x000D_ +7 (3022) 24-22-25_x000D_ +7 (3022) 24-45-58_x000D_ +7 (30241) 2-40-54_x000D_ +7 (342) 230-22-25_x000D_ +7 (343) 358-22-25_x000D_ +7 (343) 358-22-60_x000D_ +7 (343) 358-29-32_x000D_ +7 (343) 358-40-88_x000D_ +7 (343) 358-44-00_x000D_ +7 (343) 358-48-10_x000D_ +7 (343) 358-48-48_x000D_ +7 (343) 358-48-89_x000D_ +7 (343) 358-57-27_x000D_ +7 (343) 380-14-74_x000D_ +7 (343) 380-17-54_x000D_ +7 (3435) 49-42-39_x000D_ +7 (3452) 52-31-40_x000D_ +7 (3452) 52-38-48_x000D_ +7 (3462) 39-35-33_x000D_ +7 (347) 229-63-15_x000D_ +7 (347) 253-14-52_x000D_ +7 (351) 259-29-04_x000D_ +7 (351) 263-84-82_x000D_ +7 (351) 268-21-40_x000D_ +7 (351) 268-39-12_x000D_ +7 (351) 268-65-09_x000D_ +7 (3513) 69-21-40_x000D_ +7 (3812) 44-30-79_x000D_ +7 (383) 229-20-20_x000D_ +7 (383) 229-36-02_x000D_ +7 (383) 229-48-02_x000D_ +7 (383) 229-50-27_x000D_ +7 (383) 334-02-43_x000D_ +7 (3842) 32-23-79_x000D_ +7 (3842) 32-39-50_x000D_ +7 (3852) 29-20-48_x000D_ +7 (3902) 29-45-66_x000D_ +7 (3912) 23-13-28_x000D_ +7 (3912) 48-04-35_x000D_ +7 (3912) 48-05-59_x000D_ +7 (3912) 59-52-98_x000D_ +7 (3952) 63-22-46_x000D_ +7 (3952) 63-42-66_x000D_ +7 (3952) 63-84-79_x000D_ +7 (3952) 64-42-46_x000D_ +7 (3952) 64-48-48_x000D_ +7 (3952) 64-51-55_x000D_ +7 (3953) 49-79-79_x000D_ +7 (4012) 58-61-01_x000D_ +7 (4012) 58-72-02_x000D_ +7 (41656) 7-20-00_x000D_ +7 (4212) 38-12-27_x000D_ +7 (4212) 38-37-18_x000D_ +7 (4212) 38-38-80_x000D_ +7 (4212) 38-41-36_x000D_ +7 (4212) 38-47-19_x000D_ +7 (4212) 38-48-43_x000D_ +7 (4212) 38-48-48_x000D_ +7 (4212) 38-53-57_x000D_ +7 (4212) 38-81-91_x000D_ +7 (4212) 38-88-34_x000D_ +7 (4712) 55-23-00_x000D_ +7 (4712) 55-57-54_x000D_ +7 (4722) 76-03-04_x000D_ +7 (4722) 76-05-25_x000D_ +7 (4732) 48-83-14_x000D_ +7 (4732) 65-08-10_x000D_ +7 (4732) 65-08-28_x000D_ +7 (4732) 65-22-64_x000D_ +7 (4732) 65-23-51_x000D_ +7 (4732) 65-28-32_x000D_ +7 (4732) 65-38-34_x000D_ +7 (4732) 65-44-50_x000D_ +7 (4732) 65-66-22_x000D_ +7 (4732) 65-72-81_x000D_ +7 (47391) 4-17-26_x000D_ +7 (47391) 7-59-64_x000D_ +7 (47545) 3-21-40_x000D_ +7 (47545) 3-22-76_x000D_ +7 (4812) 39-52-25_x000D_ +7 (4842) 78-52-95_x000D_ +7 (4852) 49-50-02_x000D_ +7 (4852) 52-40-86_x000D_ +7 (4852) 52-52-43_x000D_ +7 (4852) 79-22-41_x000D_ +7 (4852) 79-35-60_x000D_ +7 (4852) 79-43-14_x000D_ +7 (4852) 79-44-00_x000D_ +7 (4872) 20-20-80_x000D_ +7 (4872) 20-20-93 | D20: http://www.e-disclosure.ru/portal/company.aspx?id=4543_x000D_ http://www.rzd.ru/_x000D_ http://altaitursib.ru/_x000D_ http://dss-sverdl.ru/_x000D_ http://dzvr.ru/about/structure/_x000D_ http://krw.ru/_x000D_ http://kzd.web.rzd/_x000D_ http://rzd.ru/_x000D_ http://www.cm.rzd.ru/_x000D_ http://www.css-rzd.ru/_x000D_ http://www.kras.rzd.ru/_x000D_ http://www.nrr.cm.rzd.ru/_x000D_ http://www.pkbct.ru/_x000D_ http://www.rmzhoper.ru/_x000D_ http://www.rzd.ru/ent/public/ru?STRUCTURE_ID=5185&amp;layer_id=5554&amp;refererLayerId=5553&amp;id=1015_x000D_ http://www.rzd.ru/ent/public/ru?STRUCTURE_ID=5185&amp;layer_id=5554&amp;refererLayerId=5553&amp;id=4347_x000D_ http://www.trudvsem.ru/_x000D_ http://www.uvzd.rzd.ru/_x000D_ http://www.web.rzd/_x000D_ https://www.list-org.com/go?site=804719 | E20: https://kad.arbitr.ru/Card/557c72d2-6273-4cac-8bd9-afeb68a00391 | F20: А40-34777/2024 | G20: ООО "Транспортные Технологии" | H20: 7726326069 | I20: ОАО "РЖД" | J20: 7708503727 | K20: Белозёров Олег Валентинович | L20: 781306504007 | M20: 1178136.2 | N20: 45342 | O20: 220413 | P20: 107174, город Москва, Новая Басманная ул, д. 2/1 стр. 1 | Q20: АС города Москвы | R20: Деятельность железнодорожного транспорта: грузовые перевозки (49.20) | S20: ОБЩЕСТВО С ОГРАНИЧЕННОЙ ОТВЕТСТВЕННОСТЬЮ "ТРАНСПОРТНЫЕ ТЕХНОЛОГИИ" | U20: ОТКРЫТОЕ АКЦИОНЕРНОЕ ОБЩЕСТВО "РОССИЙСКИЕ ЖЕЛЕЗНЫЕ ДОРОГИ" | W20: Заявление Исковое заявление
A21: =SUBTOTAL(103,$F$1:F21)-1 -> 20 | E21: https://kad.arbitr.ru/Card/e1dcb263-6cd8-4e69-ba94-1bac3fcde2dd | F21: А40-34716/2024 | G21: ООО "Сервис" | H21: 7703773208 | I21: ООО "Йота" | J21: 7705743537 | K21: Черноморченко Елена Ивановна | L21: 772973522707 | M21: 559266.08 | N21: 45342 | O21: 17 | P21: 119285, город Москва, Минская ул., д. 1г к. 1, помещ. XX | Q21: АС города Москвы | R21: Покупка и продажа собственного недвижимого имущества (68.1) | S21: ОБЩЕСТВО С ОГРАНИЧЕННОЙ ОТВЕТСТВЕННОСТЬЮ "СЕРВИС" | U21: ОБЩЕСТВО С ОГРАНИЧЕННОЙ ОТВЕТСТВЕННОСТЬЮ "ЙОТА" | W21: Заявление Заявление о выдаче судебного приказа
A22: =SUBTOTAL(103,$F$1:F22)-1 -> 21 | B22: taser.m@mail.ru_x000D_ kott036@rambler.ru | C22: 79266339592 | E22: https://kad.arbitr.ru/Card/b690bef0-0ead-4dab-a690-fc09a96f2c19 | F22: А40-34603/2024 | G22: ООО УК "РЭЦ" | H22: 9710031296 | I22: ООО "Тасера" | J22: 9731106440 | K22: Государев Константин Сергеевич | L22: 772904759494 | M22: 2628672 | N22: 45342 | O22: 2 | P22: 111677, город Москва, Рождественская ул, д. 4, помещ. 7/1 | Q22: АС города Москвы | R22: Управление эксплуатацией жилого фонда за вознаграждение или на договорной основе (68.32.1) | S22: ОБЩЕСТВО С ОГРАНИЧЕННОЙ ОТВЕТСТВЕННОСТЬЮ УПРАВЛЯЮЩАЯ КОМПАНИЯ "РЭЦ" | U22: ОБЩЕСТВО С ОГРАНИЧЕННОЙ ОТВЕТСТВЕННОСТЬЮ "ТАСЕРА" | W22: Заявление Исковое заявление
A23: =SUBTOTAL(103,$F$1:F23)-1 -> 22 | E23: https://kad.arbitr.ru/Card/f1bfe3fa-27de-42f6-9583-6dadf45bacfd | F23: А40-34562/2024 | G23: ООО "Пик-Комфорт" | H23: 7701208190 | I23: ООО "Московская Международная Школа" | J23: 7734447758 | K23: Сяфуков Марат Рафикович | L23: 524909899251 | M23: 3093717.4 | N23: 45342 | O23: 1 | P23: 121087, город Москва, Большая Филёвская ул, д. 3 стр. 5 | Q23: АС города Москвы | R23: Предоставление услуг по дневному уходу за детьми (88.91) | S23: ОБЩЕСТВО С ОГРАНИЧЕННОЙ ОТВЕТСТВЕННОСТЬЮ "ПИК-КОМФОРТ" | U23: ОБЩЕСТВО С ОГРАНИЧЕННОЙ ОТВЕТСТВЕННОСТЬЮ "МОСКОВСКАЯ МЕЖДУНАРОДНАЯ ШКОЛА" | W23: Заявление Исковое заявление
A24: =SUBTOTAL(103,$F$1:F24)-1 -> 23 | E24: https://kad.arbitr.ru/Card/39cba366-a73f-4c67-a4c7-95cbb1f6b842 | F24: А40-34464/2024 | G24: АО "Мосэнергосбыт" | H24: 7736520080 | I24: ООО "УК "Меркурий-Покровское" | J24: 9723113147 | K24: Кривоносов Никита Борисович | L24: 781300677677 | M24: 1921285.7 | N24: 45342 | O24: 22 | P24: 125424, город Москва, Волоколамское ш, д. 71 к. 8, помещ. 6 | Q24: АС города Москвы | R24: Управление недвижимым имуществом за вознаграждение или на договорной основе (68.32) | S24: АКЦИОНЕРНОЕ ОБЩЕСТВО "МОСЭНЕРГОСБЫТ" | U24: ОБЩЕСТВО С ОГРАНИЧЕННОЙ ОТВЕТСТВЕННОСТЬЮ "УПРАВЛЯЮЩАЯ КОМПАНИЯ "МЕРКУРИЙ-ПОКРОВСКОЕ" | W24: Заявление Исковое заявление
A25: =SUBTOTAL(103,$F$1:F25)-1 -> 24 | C25: +7 (495) 651-95-99 | E25: https://kad.arbitr.ru/Card/214c2795-f84c-4aff-a13e-6b41fd6b1e14 | F25: А40-34436/2024 | G25: АО "ФМП Групп" | H25: 7717744461 | I25: ООО "Форс Медиа" | J25: 7722551627 | K25: Алпацкая Алена Дмитриевна | L25: 344505935977 | M25: 25743568 | N25: 45342 | O25: 16 | P25: 107078, город Москва, Новорязанская ул., д. 18 стр. 17 | Q25: АС города Москвы | R25: Производство кинофильмов, видеофильмов и телевизионных программ (59.11) | S25: АКЦИОНЕРНОЕ ОБЩЕСТВО "ФМП ГРУПП" | U25: ОБЩЕСТВО С ОГРАНИЧЕННОЙ ОТВЕТСТВЕННОСТЬЮ "ФОРС МЕДИА" | W25: Заявление Исковое заявление
A26: =SUBTOTAL(103,$F$1:F26)-1 -> 25 | E26: https://kad.arbitr.ru/Card/1808edcd-160c-454b-85fe-4872fc45a59d | F26: А40-34311/2024 | G26: ООО "Яндекс.Такси" | H26: 7704340310 | I26: ООО "Премьерспорт" | J26: 7704467612 | K26: Абрамова Елена Викторовна | L26: 773202675936 | M26: 758931.9 | N26: 45342 | O26: 4 | P26: 125167, город Москва, Ленинградский пр-кт, д. 36 к. 33, эт/пом/ком 4/I/48 | Q26: АС города Москвы | R26: Деятельность фитнес-центров (93.13) | S26: ОБЩЕСТВО С ОГРАНИЧЕННОЙ ОТВЕТСТВЕННОСТЬЮ "ЯНДЕКС.ТАКСИ" | U26: ОБЩЕСТВО С ОГРАНИЧЕННОЙ ОТВЕТСТВЕННОСТЬЮ "ПРЕМЬЕРСПОРТ" | W26: Заявление Исковое заявление
A27: =SUBTOTAL(103,$F$1:F27)-1 -> 26 | C27: +7 (3412) 43-24-44_x000D_ +7 (3412) 94-39-38 | D27: http://ohranacentr.ru/ | E27: https://kad.arbitr.ru/Card/cea3d6b7-29ea-4e18-a905-9cabf0b4a8e9 | F27: А40-33963/2024 | G27: ООО "РМ-Плюс" | H27: 7715599770 | I27: ООО "Центр" | J27: 1832006126 | K27: Ощепков Константин Сергеевич | L27: 183512023747 | M27: 7162072 | N27: 45342 | O27: 31 | P27: 426053, Удмуртская Республика, город Ижевск, ул. Ворошилова, д.53 | Q27: АС города Москвы | R27: Торговля оптовая бытовыми электротоварами (46.43) | S27: ОБЩЕСТВО С ОГРАНИЧЕННОЙ ОТВЕТСТВЕННОСТЬЮ "РМ-ПЛЮС" | U27: ОБЩЕСТВО С ОГРАНИЧЕННОЙ ОТВЕТСТВЕННОСТЬЮ "ЦЕНТР" | W27: Заявление Исковое заявление
A28: =SUBTOTAL(103,$F$1:F28)-1 -> 27 | B28: dsk1.rostokino@dsk1.ru_x000D_ dsk1@dsk1.ru_x000D_ rostokino@dsk1.ru | E28: https://kad.arbitr.ru/Card/b77f47bf-5aa9-40af-bfb9-15510b6c86ba | F28: А40-33988/2024 | G28: АО "Первый Автокомбинат" имени Г.Л. Краузе | H28: 7734032873 | I28: ООО "Дск1-Ростокино" | J28: 7716917390 | M28: 1893833.2 | N28: 45342 | O28: 38 | P28: 129343, город Москва, ул. Амундсена, д. 2 стр. 18, эт 1 пом I ком 2 | Q28: АС города Москвы | R28: Производство готовых строительных изделий из бетона, цемента и искусственного камня (23.61.1) | S28: ОРДЕНА ТРУДОВОГО КРАСНОГО ЗНАМЕНИ АКЦИОНЕРНОЕ ОБЩЕСТВО "ПЕРВЫЙ АВТОКОМБИНАТ" ИМЕНИ Г.Л. КРАУЗЕ | U28: ОБЩЕСТВО С ОГРАНИЧЕННОЙ ОТВЕТСТВЕННОСТЬЮ "ДСК1-РОСТОКИНО" | W28: Заявление Исковое заявление
A29: =SUBTOTAL(103,$F$1:F29)-1 -> 28 | B29: soyuzsnabgroup@mail.ru | C29: +7 (8452) 25-99-20_x000D_ +7 (8452) 49-73-95_x000D_ +7 (8453) 53-64-28 | E29: https://kad.arbitr.ru/Card/d49cad1e-305a-486e-b3d2-21d32f7d3b09 | F29: А40-33916/2024 | G29: ООО "ЗНГС-Прометей" | H29: 7706214286 | I29: ООО "ССГ" | J29: 6450083544 | K29: Жуков Андрей Леонидович | L29: 645302844668 | M29: 70983587 | N29: 45342 | O29: 23 | P29: 125481, город Москва, Фомичёвой ул, д. 16 к. 3, кв. 197 | Q29: АС города Москвы | R29: Строительство жилых и нежилых зданий (41.20) | S29: ОБЩЕСТВО С ОГРАНИЧЕННОЙ ОТВЕТСТВЕННОСТЬЮ "ЗАКНЕФТЕГАЗСТРОЙ-ПРОМЕТЕЙ" | U29: ОБЩЕСТВО С ОГРАНИЧЕННОЙ ОТВЕТСТВЕННОСТЬЮ "СОЮЗСТРОЙГРУПП" | W29: Заявление Исковое заявление
A30: =SUBTOTAL(103,$F$1:F30)-1 -> 29 | B30: andrey79_777@mail.ru | E30: https://kad.arbitr.ru/Card/69bde3c4-c1d0-4d8d-9eaf-557edcad0105 | F30: А40-33857/2024 | G30: ООО "Веста" | H30: 7726454159 | I30: ООО "Альянс-Строй" | J30: 5614084072 | K30: Ляшко Анатолий Иванович | L30: 561600203503 | M30: 564253.97 | N30: 45342 | O30: 5 | P30: 462422, Оренбургская область, город Орск, ул. К.Маркса, д. 76 | Q30: АС города Москвы | R30: Разработка гравийных и песчаных карьеров, добыча глины и каолина (08.12) | S30: ОБЩЕСТВО С ОГРАНИЧЕННОЙ ОТВЕТСТВЕННОСТЬЮ "ВЕСТА" | U30: ОБЩЕСТВО С ОГРАНИЧЕННОЙ ОТВЕТСТВЕННОСТЬЮ "АЛЬЯНС-СТРОЙ" | W30: Заявление Исковое заявление
A31: =SUBTOTAL(103,$F$1:F31)-1 -> 30 | B31: dsu68@bk.ru | C31: +7 (915) 879-88-34 | E31: https://kad.arbitr.ru/Card/95c56ee2-36ab-4968-8ffd-27649babb069 | F31: А40-33816/2024 | G31: ООО "ТДМ" | H31: 9717102115 | I31: ООО "Дсу-68" | J31: 6829156219 | K31: Хабоян Армен Гасанович | L31: 682968058219 | M31: 992375.71 | N31: 45342 | O31: 2 | P31: 392526, Тамбовская область, п Строитель, Дорожно-Строительная ул, стр. 46а, офис 1 | Q31: АС города Москвы | R31: Строительство автомобильных дорог и автомагистралей (42.11) | S31: ОБЩЕСТВО С ОГРАНИЧЕННОЙ ОТВЕТСТВЕННОСТЬЮ "ТОРГОВЫЙ ДОМ МАГИСТРАЛЬ" | U31: ОБЩЕСТВО С ОГРАНИЧЕННОЙ ОТВЕТСТВЕННОСТЬЮ "ДСУ-68" | W31: Определение О принятии заявления к производству с рассмотрением в порядке упрощенного производства
A32: =SUBTOTAL(103,$F$1:F32)-1 -> 31 | B32: 1574104@mail.ru | C32: +7 (985) 776-86-74 | E32: https://kad.arbitr.ru/Card/9d51caec-6033-4d4a-bb06-06885a5c48c2 | F32: А40-33867/2024 | G32: АО "СТВ" | H32: 7725810365 | I32: ООО "Е ТВ" | J32: 7714353928 | K32: Кирсанова Виктория Викторовна | L32: 773102302803 | M32: 3186869.7 | N32: 45342 | O32: 7 | P32: 125493, город Москва, Смольная ул, д. 12, этаж 1 помещ. 189з | Q32: АС города Москвы | R32: Деятельность в области телевизионного вещания (60.20) | S32: АКЦИОНЕРНОЕ ОБЩЕСТВО "СПУТНИКОВОЕ ТЕЛЕВИДЕНИЕ" | U32: ОБЩЕСТВО С ОГРАНИЧЕННОЙ ОТВЕТСТВЕННОСТЬЮ "ЕТЕРРА ТВ" | W32: Заявление Исковое заявление
A33: =SUBTOTAL(103,$F$1:F33)-1 -> 32 | C33: +7 (499) 126-66-08_x000D_ +7 (495) 942-71-71_x000D_ +7 (495) 236-13-15_x000D_ +7 (499) 550-00-55_x000D_ +7 (495) 223-40-25, доб 607_x000D_ +7 (495) 987-31-66_x000D_ +7 (495) 727-25-82_x000D_ +7 (495) 727-24-24, доб 5834_x000D_ +7 (495) 223-40-20, доб 5662_x000D_ +7 (495) 727-24-75_x000D_ +7 (495) 983-06-78_x000D_ +7 (495) 758-68-69_x000D_ +7 (495) 727-25-37_x000D_ +7 (495) 223-40-20, доб 5607_x000D_ +7 (495) 942-95-95_x000D_ +7 (495) 942-80-80_x000D_ +7 (495) 948-62-80_x000D_ +7 (495) 983-06-71_x000D_ +7 (495) 222-22-22, доб 2_x000D_ +7 (495) 727-25-24_x000D_ +7 (495) 727-25-23_x000D_ +7 (495) 727-26-26_x000D_ +7 (495) 987-42-33, доб 4177_x000D_ +7 (495) 223-40-20_x000D_ +7 (495) 727-24-24_x000D_ +7 (495) 727-26-25_x000D_ +7 (495) 727-25-98_x000D_ +7 (495) 000-00-00_x000D_ +7 (495) 727-80-80_x000D_ +7 (495) 223-40-20, доб 5657_x000D_ +7 (495) 228-12-23_x000D_ +7 (495) 126-26-35 | E33: https://kad.arbitr.ru/Card/1d623689-4729-45ad-8ecd-a0302e2dec48 | F33: А40-33905/2024 | G33: ООО "Элфокс" | H33: 5012055483 | I33: ООО "Крокус" | J33: 7728115183 | K33: Мросвирина Марина Николаевна | L33: 772503697297 | M33: 3207953.9 | N33: 45342 | O33: 2487 | P33: 107120, город Москва, ул. Земляной Вал, д.41, кв.2 | Q33: АС города Москвы | R33: Сведения о видах деятельности отсутствуют. | S33: ОБЩЕСТВО С ОГРАНИЧЕННОЙ ОТВЕТСТВЕННОСТЬЮ "ЭЛФОКС" | U33: ОБЩЕСТВО С ОГРАНИЧЕННОЙ ОТВЕТСТВЕННОСТЬЮ "КРОКУС 02" | W33: Определение О принятии искового заявления (заявления) к производству
A34: =SUBTOTAL(103,$F$1:F34)-1 -> 33 | B34: bfm@btsrvs.ru | C34: +7 (495) 230-55-87 | E34: https://kad.arbitr.ru/Card/a472e31e-f9ad-4985-8a37-94a17820d117 | F34: А40-34623/2024 | G34: ПАО "Промсвязьбанк" | H34: 7744000912 | I34: ООО "БТС" | J34: 5040165689 | K34: Мухтаров Мирзотуйчи Мирзоазизович | L34: 742007514797 | M34: 2537142 | N34: 45342 | O34: 5 | P34: 142322, Московская область, с Новый Быт, тер. Коммунальная, ком. 1. азс | Q34: АС города Москвы | R34: Техническое обслуживание и ремонт автотранспортных средств (45.20) | S34: ПУБЛИЧНОЕ АКЦИОНЕРНОЕ ОБЩЕСТВО "ПРОМСВЯЗЬБАНК" | U34: ОБЩЕСТВО С ОГРАНИЧЕННОЙ ОТВЕТСТВЕННОСТЬЮ "БОСС ТРАК СЕРВИС" | W34: Заявление Исковое заявление
A35: =SUBTOTAL(103,$F$1:F35)-1 -> 34 | B35: info@pfvis.ru_x000D_ bulavinova3@yandex.ru_x000D_ a.dubrovskih@vis-group.ru_x000D_ timofeeva_sl@pfvis.ru_x000D_ info@pfvis-msk.ru_x000D_ nk@pfvis.ru | C35: +7 (495) 789-85-55_x000D_ +7 (495) 789-85-56_x000D_ +7 (3496) 39-81-12, доб 55_x000D_ +7 (495) 789-85-55, доб 55_x000D_ +7 (495) 789-85-55, доб 7_x000D_ +7 (921) 321-63-10_x000D_ +7 (495) 789-85-55, доб 1858_x000D_ +7 (495) 789-85-55, доб 1875_x000D_ +7 (495) 778-85-55_x000D_ +7 (495) 779-85-56_x000D_ +7 (812) 336-69-90_x000D_ +7 (812) 336-69-91_x000D_ +7 (81371) 3-03-17_x000D_ +7 (495) 781-08-55 | E35: https://kad.arbitr.ru/Card/9a38845c-276c-4df2-af71-4f068723b31e | F35: А40-33896/2024 | G35: ООО "СЗТК" | H35: 7841372708 | I35: ООО "ПФ "ВИС" | J35: 7816158919 | K35: Юдин Сергей Сергеевич | L35: 773127081176 | M35: 1169834.1 | N35: 45342 | O35: 333 | P35: 188300, Ленинградская область, Гатчинский район, город Гатчина, ул. 7 Армии, д. 22а, помещ. 10 | Q35: АС города Москвы | R35: Строительство жилых и нежилых зданий (41.20) | S35: ОБЩЕСТВО С ОГРАНИЧЕННОЙ ОТВЕТСТВЕННОСТЬЮ "СЕВЕРО-ЗАПАДНАЯ ТРУБНАЯ КОМПАНИЯ" | U35: ОБЩЕСТВО С ОГРАНИЧЕННОЙ ОТВЕТСТВЕННОСТЬЮ "ПРОИЗВОДСТВЕННАЯ ФИРМА "ВИС" | W35: Заявление Исковое заявление
A36: =SUBTOTAL(103,$F$1:F36)-1 -> 35 | C36: +7 (922) 639-44-44 | E36: https://kad.arbitr.ru/Card/e587eb78-9515-4587-b99b-0bea7f445a27 | F36: А40-33981/2024 | G36: АО "НЛТ" | H36: 7708334941 | I36: ООО "Промстрой" | J36: 7447240439 | K36: Оганян Гайк Сергеевич | L36: 745312418887 | M36: 4099713.4 | N36: 45342 | O36: 11 | P36: 350010, Краснодарский край, г Краснодар, Зиповская ул, д. 5б, офис 61 | Q36: АС города Москвы | R36: Строительство жилых и нежилых зданий (41.20) | S36: АКЦИОНЕРНОЕ ОБЩЕСТВО "НАЦИОНАЛЬНЫЕ ЛОГИСТИЧЕСКИЕ ТЕХНОЛОГИИ" | U36: ОБЩЕСТВО С ОГРАНИЧЕННОЙ ОТВЕТСТВЕННОСТЬЮ "ПРОМСТРОЙ" | W36: Заявление Исковое заявление
A37: =SUBTOTAL(103,$F$1:F37)-1 -> 36 | B37: avgkh.podolsk@gmail.com_x000D_ nikituk.notarius@yandex.ru_x000D_ buh@avgkh.ru | C37: +7 (495) 214-97-55_x000D_ +7 (498) 505-95-47_x000D_ 8 (800) 250-43-88_x000D_ +7 (495) 741-93-10 | E37: https://kad.arbitr.ru/Card/cf94e8b4-8a27-4853-80c2-c3fc1da7bfbb | F37: А40-34342/2024 | G37: АО "Мосэнергосбыт" | H37: 7736520080 | I37: ООО "УК Август ЖКХ" | J37: 5045055143 | K37: Киляков Игорь Владимирович | L37: 500109604283 | M37: 516806.26 | N37: 45342 | O37: 1236 | P37: 142118, Московская область, город Подольск, ул. 43-й Армии, д. 17, помещ. 4 | Q37: АС города Москвы | R37: Управление недвижимым имуществом за вознаграждение или на договорной основе (68.32) | S37: АКЦИОНЕРНОЕ ОБЩЕСТВО "МОСЭНЕРГОСБЫТ" | U37: ОБЩЕСТВО С ОГРАНИЧЕННОЙ ОТВЕТСТВЕННОСТЬЮ "УПРАВЛЯЮЩАЯ КОМПАНИЯ АВГУСТ ЖКХ" | W37: Заявление Исковое заявление
A38: =SUBTOTAL(103,$F$1:F38)-1 -> 37 | B38: rzd@rzd.ru_x000D_ poddymnikovaov@wsr.ru_x000D_ DKRE-Mahalov@kbsh.rzd.ru_x000D_ dtv-3.rzd@bk.ru_x000D_ echekunova@skzd.rzd.ru_x000D_ EPBelenkaiakr@skzd.rzd.ru_x000D_ fax@css.rzd.ru_x000D_ gorkdmkadr@gmail.com_x000D_ kuzmenkovagv@center.rzd.ru_x000D_ mivc@mzd.ru_x000D_ mrzd_KostrovaSA@orw.ru_x000D_ NEKolesnikova@serw.ru_x000D_ Ngs_s@svrw.ru_x000D_ sevtcfto@yandex.ru_x000D_ TuizovaTA@mail.zabtrans.ru | C38: +7 (499) 262-99-01_x000D_ +7 (499) 262-10-02_x000D_ 8 (800) 775-00-00_x000D_ +7 (4852) 52-18-30_x000D_ +7 (3012) 28-25-04_x000D_ +7 (3022) 22-33-05_x000D_ +7 (3022) 22-46-03_x000D_ +7 (3022) 22-46-72_x000D_ +7 (3022) 22-75-05_x000D_ +7 (3022) 24-18-00_x000D_ +7 (3022) 24-22-25_x000D_ +7 (3022) 24-45-58_x000D_ +7 (30241) 2-40-54_x000D_ +7 (342) 230-22-25_x000D_ +7 (343) 358-22-25_x000D_ +7 (343) 358-22-60_x000D_ +7 (343) 358-29-32_x000D_ +7 (343) 358-40-88_x000D_ +7 (343) 358-44-00_x000D_ +7 (343) 358-48-10_x000D_ +7 (343) 358-48-48_x000D_ +7 (343) 358-48-89_x000D_ +7 (343) 358-57-27_x000D_ +7 (343) 380-14-74_x000D_ +7 (343) 380-17-54_x000D_ +7 (3435) 49-42-39_x000D_ +7 (3452) 52-31-40_x000D_ +7 (3452) 52-38-48_x000D_ +7 (3462) 39-35-33_x000D_ +7 (347) 229-63-15_x000D_ +7 (347) 253-14-52_x000D_ +7 (351) 259-29-04_x000D_ +7 (351) 263-84-82_x000D_ +7 (351) 268-21-40_x000D_ +7 (351) 268-39-12_x000D_ +7 (351) 268-65-09_x000D_ +7 (3513) 69-21-40_x000D_ +7 (3812) 44-30-79_x000D_ +7 (383) 229-20-20_x000D_ +7 (383) 229-36-02_x000D_ +7 (383) 229-48-02_x000D_ +7 (383) 229-50-27_x000D_ +7 (383) 334-02-43_x000D_ +7 (3842) 32-23-79_x000D_ +7 (3842) 32-39-50_x000D_ +7 (3852) 29-20-48_x000D_ +7 (3902) 29-45-66_x000D_ +7 (3912) 23-13-28_x000D_ +7 (3912) 48-04-35_x000D_ +7 (3912) 48-05-59_x000D_ +7 (3912) 59-52-98_x000D_ +7 (3952) 63-22-46_x000D_ +7 (3952) 63-42-66_x000D_ +7 (3952) 63-84-79_x000D_ +7 (3952) 64-42-46_x000D_ +7 (3952) 64-48-48_x000D_ +7 (3952) 64-51-55_x000D_ +7 (3953) 49-79-79_x000D_ +7 (4012) 58-61-01_x000D_ +7 (4012) 58-72-02_x000D_ +7 (41656) 7-20-00_x000D_ +7 (4212) 38-12-27_x000D_ +7 (4212) 38-37-18_x000D_ +7 (4212) 38-38-80_x000D_ +7 (4212) 38-41-36_x000D_ +7 (4212) 38-47-19_x000D_ +7 (4212) 38-48-43_x000D_ +7 (4212) 38-48-48_x000D_ +7 (4212) 38-53-57_x000D_ +7 (4212) 38-81-91_x000D_ +7 (4212) 38-88-34_x000D_ +7 (4712) 55-23-00_x000D_ +7 (4712) 55-57-54_x000D_ +7 (4722) 76-03-04_x000D_ +7 (4722) 76-05-25_x000D_ +7 (4732) 48-83-14_x000D_ +7 (4732) 65-08-10_x000D_ +7 (4732) 65-08-28_x000D_ +7 (4732) 65-22-64_x000D_ +7 (4732) 65-23-51_x000D_ +7 (4732) 65-28-32_x000D_ +7 (4732) 65-38-34_x000D_ +7 (4732) 65-44-50_x000D_ +7 (4732) 65-66-22_x000D_ +7 (4732) 65-72-81_x000D_ +7 (47391) 4-17-26_x000D_ +7 (47391) 7-59-64_x000D_ +7 (47545) 3-21-40_x000D_ +7 (47545) 3-22-76_x000D_ +7 (4812) 39-52-25_x000D_ +7 (4842) 78-52-95_x000D_ +7 (4852) 49-50-02_x000D_ +7 (4852) 52-40-86_x000D_ +7 (4852) 52-52-43_x000D_ +7 (4852) 79-22-41_x000D_ +7 (4852) 79-35-60_x000D_ +7 (4852) 79-43-14_x000D_ +7 (4852) 79-44-00_x000D_ +7 (4872) 20-20-80_x000D_ +7 (4872) 20-20-93 | D38: http://www.e-disclosure.ru/portal/company.aspx?id=4543_x000D_ http://www.rzd.ru/_x000D_ http://altaitursib.ru/_x000D_ http://dss-sverdl.ru/_x000D_ http://dzvr.ru/about/structure/_x000D_ http://krw.ru/_x000D_ http://kzd.web.rzd/_x000D_ http://rzd.ru/_x000D_ http://www.cm.rzd.ru/_x000D_ http://www.css-rzd.ru/_x000D_ http://www.kras.rzd.ru/_x000D_ http://www.nrr.cm.rzd.ru/_x000D_ http://www.pkbct.ru/_x000D_ http://www.rmzhoper.ru/_x000D_ http://www.rzd.ru/ent/public/ru?STRUCTURE_ID=5185&amp;layer_id=5554&amp;refererLayerId=5553&amp;id=1015_x000D_ http://www.rzd.ru/ent/public/ru?STRUCTURE_ID=5185&amp;layer_id=5554&amp;refererLayerId=5553&amp;id=4347_x000D_ http://www.trudvsem.ru/_x000D_ http://www.uvzd.rzd.ru/_x000D_ http://www.web.rzd/_x000D_ https://www.list-org.com/go?site=804719 | E38: https://kad.arbitr.ru/Card/f7ee1dba-d0ea-400a-a63f-f227653196e9 | F38: А40-34432/2024 | G38: ООО "ЧНК" | H38: 2337044305 | I38: ОАО "РЖД" | J38: 7708503727 | K38: Белозёров Олег Валентинович | L38: 781306504007 | M38: 619878.84 | N38: 45342 | O38: 220414 | P38: 107174, город Москва, Новая Басманная ул, д. 2/1 стр. 1 | Q38: АС города Москвы | R38: Деятельность железнодорожного транспорта: грузовые перевозки (49.20) | S38: ОБЩЕСТВО С ОГРАНИЧЕННОЙ ОТВЕТСТВЕННОСТЬЮ "ЧЕРНОМОРСКАЯ НЕФТЯНАЯ КОМПАНИЯ" | U38: ОТКРЫТОЕ АКЦИОНЕРНОЕ ОБЩЕСТВО "РОССИЙСКИЕ ЖЕЛЕЗНЫЕ ДОРОГИ" | W38: Заявление Исковое заявление
A39: =SUBTOTAL(103,$F$1:F39)-1 -> 38 | B39: andnik@fastmail.com_x000D_ ao@fortex-group.ru_x000D_ 311416@mail.ru_x000D_ nfo@glavms.ru | C39: +7 (495) 708-31-35_x000D_ +7 (495) 137-56-25_x000D_ +7 (985) 163-53-43_x000D_ +7 (495) 921-31-21 | E39: https://kad.arbitr.ru/Card/282f0533-6141-4bee-b3b8-1b92e89db46c | F39: А40-34287/2024 | G39: ООО "СМ-Групп" | H39: 7724325253 | I39: ООО "Главмонтажстрой" | J39: 7730699401 | K39: Еремичев Сергей Викторович | L39: 772800624206 | M39: 7142160 | N39: 45342 | O39: 40 | P39: 121059, город Москва, Брянская ул., д. 2, эт антресоль1 пом III каб 8 | Q39: АС города Москвы | R39: Строительство жилых и нежилых зданий (41.20) | S39: ОБЩЕСТВО С ОГРАНИЧЕННОЙ ОТВЕТСТВЕННОСТЬЮ "СТРОИТЕЛЬНЫЕ МАШИНЫ" | U39: ОБЩЕСТВО С ОГРАНИЧЕННОЙ ОТВЕТСТВЕННОСТЬЮ "ГЛАВМОНТАЖСТРОЙ" | W39: Заявление Исковое заявление
A40: =SUBTOTAL(103,$F$1:F40)-1 -> 39 | B40: info@ksum.ru_x000D_ oks2902@yandex.ru | C40: +7 (48336) 4-02-66_x000D_ +7 (48336) 4-24-85_x000D_ +7 (48336) 4-69-37_x000D_ +7 (916) 684-81-94_x000D_ +7 (910) 734-44-86 | E40: https://kad.arbitr.ru/Card/7e8e1181-57c2-4374-9493-60d73b448183 | F40: А40-34248/2024 | G40: ФГУП "Эндофарм" | H40: 7722059711 | I40: ООО "Клинцовское Сум" | J40: 3241006974 | K40: Лысаков Александр Васильевич | L40: 320301337305 | M40: 754139.65 | N40: 45342 | O40: 42 | P40: 107014, город Москва, 1-Я Боевская ул, д. 2/12 стр. 4, помещ. 1/1 | Q40: АС города Москвы | R40: Строительство жилых и нежилых зданий (41.2) | S40: ФЕДЕРАЛЬНОЕ ГОСУДАРСТВЕННОЕ УНИТАРНОЕ ПРЕДПРИЯТИЕ "МОСКОВСКИЙ ЭНДОКРИННЫЙ ЗАВОД" | U40: ОБЩЕСТВО С ОГРАНИЧЕННОЙ ОТВЕТСТВЕННОСТЬЮ "КЛИНЦОВСКОЕ СПЕЦУПРАВЛЕНИЕ МЕХАНИЗАЦИИ" | W40: Заявление Исковое заявление
...

Sheet Рассылка
A1: Телефон | B1: Номер дела | C1: Истец сокращенно | D1: Ответчик сокращенно | E1: ИО руководителя ответчика | F1: Сумма иска | G1: Дата подачи иска | H1: Руководитель ответчика
A2: =IF(COUNTIF(Дела!$A:$A,ROW()-1)>0,VLOOKUP(ROW()-1,Дела!$A:$C,3,0),"") -> +7 (910) 131-18-94_x000D_ +7 (910) 143-33-00 | B2: =IF(COUNTIF(Дела!$A:$A,ROW()-1)>0,VLOOKUP(ROW()-1,Дела!$A:$F,6,0),"") -> А40-34987/2024 | C2: =IF(COUNTIF(Дела!$A:$A,ROW()-1)>0,VLOOKUP(ROW()-1,Дела!$A:$G,7,0),"") -> ООО "Комплексная Безопасность" | D2: =IF(COUNTIF(Дела!$A:$A,ROW()-1)>0,VLOOKUP(ROW()-1,Дела!$A:$I,9,0),"") -> ООО "Артал Строй" | E2: =IF(H2="","",MID(H2,SEARCH(" ",H2)+1,1000)) -> Артем Игоревич | F2: =IF(COUNTIF(Дела!$A:$A,ROW()-1)>0,VLOOKUP(ROW()-1,Дела!$A:$M,13,0),"") -> 4489799 | G2: =IF(COUNTIF(Дела!$A:$A,ROW()-1)>0,VLOOKUP(ROW()-1,Дела!$A:$N,14,0),"") -> 45342 | H2: =IF(COUNTIF(Дела!$A:$A,ROW()-1)>0,VLOOKUP(ROW()-1,Дела!$A:$K,11,0),"") -> Родионов Артем Игоревич
A3: =IF(COUNTIF(Дела!$A:$A,ROW()-1)>0,VLOOKUP(ROW()-1,Дела!$A:$C,3,0),"") -> 0 | B3: =IF(COUNTIF(Дела!$A:$A,ROW()-1)>0,VLOOKUP(ROW()-1,Дела!$A:$F,6,0),"") -> А40-34970/2024 | C3: =IF(COUNTIF(Дела!$A:$A,ROW()-1)>0,VLOOKUP(ROW()-1,Дела!$A:$G,7,0),"") -> ИФНС России № 10 по Г. Москве | D3: =IF(COUNTIF(Дела!$A:$A,ROW()-1)>0,VLOOKUP(ROW()-1,Дела!$A:$I,9,0),"") -> ООО "Фортуна" | E3: =IF(H3="","",MID(H3,SEARCH(" ",H3)+1,1000)) -> Олча Май Оглу | F3: =IF(COUNTIF(Дела!$A:$A,ROW()-1)>0,VLOOKUP(ROW()-1,Дела!$A:$M,13,0),"") -> 3174989.9 | G3: =IF(COUNTIF(Дела!$A:$A,ROW()-1)>0,VLOOKUP(ROW()-1,Дела!$A:$N,14,0),"") -> 45342 | H3: =IF(COUNTIF(Дела!$A:$A,ROW()-1)>0,VLOOKUP(ROW()-1,Дела!$A:$K,11,0),"") -> Ооржак Олча Май Оглу
A4: =IF(COUNTIF(Дела!$A:$A,ROW()-1)>0,VLOOKUP(ROW()-1,Дела!$A:$C,3,0),"") -> +7 (499) 262-99-01_x000D_ +7 (499) 262-10-02_x000D_ 8 (800) 775-00-00_x000D_ +7 (4852) 52-18-30_x000D_ +7 (3012) 28-25-04_x000D_ +7 (3022) 22-33-05_x000D_ +7 (3022) 22-46-03_x000D_ +7 (3022) 22-46-72_x000D_ +7 (3022) 22-75-05_x000D_ +7 (3022) 24-18-00_x000D_ +7 (3022) 24-22-25_x000D_ +7 (3022) 24-45-58_x000D_ +7 (30241) 2-40-54_x000D_ +7 (342) 230-22-25_x000D_ +7 (343) 358-22-25_x000D_ +7 (343) 358-22-60_x000D_ +7 (343) 358-29-32_x000D_ +7 (343) 358-40-88_x000D_ +7 (343) 358-44-00_x000D_ +7 (343) 358-48-10_x000D_ +7 (343) 358-48-48_x000D_ +7 (343) 358-48-89_x000D_ +7 (343) 358-57-27_x000D_ +7 (343) 380-14-74_x000D_ +7 (343) 380-17-54_x000D_ +7 (3435) 49-42-39_x000D_ +7 (3452) 52-31-40_x000D_ +7 (3452) 52-38-48_x000D_ +7 (3462) 39-35-33_x000D_ +7 (347) 229-63-15_x000D_ +7 (347) 253-14-52_x000D_ +7 (351) 259-29-04_x000D_ +7 (351) 263-84-82_x000D_ +7 (351) 268-21-40_x000D_ +7 (351) 268-39-12_x000D_ +7 (351) 268-65-09_x000D_ +7 (3513) 69-21-40_x000D_ +7 (3812) 44-30-79_x000D_ +7 (383) 229-20-20_x000D_ +7 (383) 229-36-02_x000D_ +7 (383) 229-48-02_x000D_ +7 (383) 229-50-27_x000D_ +7 (383) 334-02-43_x000D_ +7 (3842) 32-23-79_x000D_ +7 (3842) 32-39-50_x000D_ +7 (3852) 29-20-48_x000D_ +7 (3902) 29-45-66_x000D_ +7 (3912) 23-13-28_x000D_ +7 (3912) 48-04-35_x000D_ +7 (3912) 48-05-59_x000D_ +7 (3912) 59-52-98_x000D_ +7 (3952) 63-22-46_x000D_ +7 (3952) 63-42-66_x000D_ +7 (3952) 63-84-79_x000D_ +7 (3952) 64-42-46_x000D_ +7 (3952) 64-48-48_x000D_ +7 (3952) 64-51-55_x000D_ +7 (3953) 49-79-79_x000D_ +7 (4012) 58-61-01_x000D_ +7 (4012) 58-72-02_x000D_ +7 (41656) 7-20-00_x000D_ +7 (4212) 38-12-27_x000D_ +7 (4212) 38-37-18_x000D_ +7 (4212) 38-38-80_x000D_ +7 (4212) 38-41-36_x000D_ +7 (4212) 38-47-19_x000D_ +7 (4212) 38-48-43_x000D_ +7 (4212) 38-48-48_x000D_ +7 (4212) 38-53-57_x000D_ +7 (4212) 38-81-91_x000D_ +7 (4212) 38-88-34_x000D_ +7 (4712) 55-23-00_x000D_ +7 (4712) 55-57-54_x000D_ +7 (4722) 76-03-04_x000D_ +7 (4722) 76-05-25_x000D_ +7 (4732) 48-83-14_x000D_ +7 (4732) 65-08-10_x000D_ +7 (4732) 65-08-28_x000D_ +7 (4732) 65-22-64_x000D_ +7 (4732) 65-23-51_x000D_ +7 (4732) 65-28-32_x000D_ +7 (4732) 65-38-34_x000D_ +7 (4732) 65-44-50_x000D_ +7 (4732) 65-66-22_x000D_ +7 (4732) 65-72-81_x000D_ +7 (47391) 4-17-26_x000D_ +7 (47391) 7-59-64_x000D_ +7 (47545) 3-21-40_x000D_ +7 (47545) 3-22-76_x000D_ +7 (4812) 39-52-25_x000D_ +7 (4842) 78-52-95_x000D_ +7 (4852) 49-50-02_x000D_ +7 (4852) 52-40-86_x000D_ +7 (4852) 52-52-43_x000D_ +7 (4852) 79-22-41_x000D_ +7 (4852) 79-35-60_x000D_ +7 (4852) 79-43-14_x000D_ +7 (4852) 79-44-00_x000D_ +7 (4872) 20-20-80_x000D_ +7 (4872) 20-20-93 | B4: =IF(COUNTIF(Дела!$A:$A,ROW()-1)>0,VLOOKUP(ROW()-1,Дела!$A:$F,6,0),"") -> А40-34838/2024 | C4: =IF(COUNTIF(Дела!$A:$A,ROW()-1)>0,VLOOKUP(ROW()-1,Дела!$A:$G,7,0),"") -> АО "Нефтетранссервис" | D4: =IF(COUNTIF(Дела!$A:$A,ROW()-1)>0,VLOOKUP(ROW()-1,Дела!$A:$I,9,0),"") -> ОАО "РЖД" | E4: =IF(H4="","",MID(H4,SEARCH(" ",H4)+1,1000)) -> Олег Валентинович | F4: =IF(COUNTIF(Дела!$A:$A,ROW()-1)>0,VLOOKUP(ROW()-1,Дела!$A:$M,13,0),"") -> 1118159 | G4: =IF(COUNTIF(Дела!$A:$A,ROW()-1)>0,VLOOKUP(ROW()-1,Дела!$A:$N,14,0),"") -> 45342 | H4: =IF(COUNTIF(Дела!$A:$A,ROW()-1)>0,VLOOKUP(ROW()-1,Дела!$A:$K,11,0),"") -> Белозёров Олег Валентинович
A5: =IF(COUNTIF(Дела!$A:$A,ROW()-1)>0,VLOOKUP(ROW()-1,Дела!$A:$C,3,0),"") -> +7 (916) 428-25-05 | B5: =IF(COUNTIF(Дела!$A:$A,ROW()-1)>0,VLOOKUP(ROW()-1,Дела!$A:$F,6,0),"") -> А40-34726/2024 | C5: =IF(COUNTIF(Дела!$A:$A,ROW()-1)>0,VLOOKUP(ROW()-1,Дела!$A:$G,7,0),"") -> ООО "Акрополь Инжиниринг" | D5: =IF(COUNTIF(Дела!$A:$A,ROW()-1)>0,VLOOKUP(ROW()-1,Дела!$A:$I,9,0),"") -> ООО "НЖС" | E5: =IF(H5="","",MID(H5,SEARCH(" ",H5)+1,1000)) -> Константин Юрьевич | F5: =IF(COUNTIF(Дела!$A:$A,ROW()-1)>0,VLOOKUP(ROW()-1,Дела!$A:$M,13,0),"") -> 4306490.7 | G5: =IF(COUNTIF(Дела!$A:$A,ROW()-1)>0,VLOOKUP(ROW()-1,Дела!$A:$N,14,0),"") -> 45342 | H5: =IF(COUNTIF(Дела!$A:$A,ROW()-1)>0,VLOOKUP(ROW()-1,Дела!$A:$K,11,0),"") -> Шевацуков Константин Юрьевич
A6: =IF(COUNTIF(Дела!$A:$A,ROW()-1)>0,VLOOKUP(ROW()-1,Дела!$A:$C,3,0),"") -> 0 | B6: =IF(COUNTIF(Дела!$A:$A,ROW()-1)>0,VLOOKUP(ROW()-1,Дела!$A:$F,6,0),"") -> А40-34801/2024 | C6: =IF(COUNTIF(Дела!$A:$A,ROW()-1)>0,VLOOKUP(ROW()-1,Дела!$A:$G,7,0),"") -> ООО "Екс-Групп" | D6: =IF(COUNTIF(Дела!$A:$A,ROW()-1)>0,VLOOKUP(ROW()-1,Дела!$A:$I,9,0),"") -> ИП Гасангусейнов Вазир Султанович | E6: =IF(H6="","",MID(H6,SEARCH(" ",H6)+1,1000)) -> Вазир Султанович | F6: =IF(COUNTIF(Дела!$A:$A,ROW()-1)>0,VLOOKUP(ROW()-1,Дела!$A:$M,13,0),"") -> 611481 | G6: =IF(COUNTIF(Дела!$A:$A,ROW()-1)>0,VLOOKUP(ROW()-1,Дела!$A:$N,14,0),"") -> 45342 | H6: =IF(COUNTIF(Дела!$A:$A,ROW()-1)>0,VLOOKUP(ROW()-1,Дела!$A:$K,11,0),"") -> Гасангусейнов Вазир Султанович
A7: =IF(COUNTIF(Дела!$A:$A,ROW()-1)>0,VLOOKUP(ROW()-1,Дела!$A:$C,3,0),"") -> +7 (495) 120-28-80 | B7: =IF(COUNTIF(Дела!$A:$A,ROW()-1)>0,VLOOKUP(ROW()-1,Дела!$A:$F,6,0),"") -> А40-34707/2024 | C7: =IF(COUNTIF(Дела!$A:$A,ROW()-1)>0,VLOOKUP(ROW()-1,Дела!$A:$G,7,0),"") -> Департамент городского Имущества Города Москвы | D7: =IF(COUNTIF(Дела!$A:$A,ROW()-1)>0,VLOOKUP(ROW()-1,Дела!$A:$I,9,0),"") -> ООО "Горячий Ключ" | E7: =IF(H7="","",MID(H7,SEARCH(" ",H7)+1,1000)) -> Алигулу Ильгар Оглы | F7: =IF(COUNTIF(Дела!$A:$A,ROW()-1)>0,VLOOKUP(ROW()-1,Дела!$A:$M,13,0),"") -> 663120.56 | G7: =IF(COUNTIF(Дела!$A:$A,ROW()-1)>0,VLOOKUP(ROW()-1,Дела!$A:$N,14,0),"") -> 45342 | H7: =IF(COUNTIF(Дела!$A:$A,ROW()-1)>0,VLOOKUP(ROW()-1,Дела!$A:$K,11,0),"") -> Асгарли Алигулу Ильгар Оглы
